2025-04-01 18:04:32 - __main__ - ERROR - An error occurred: download_audio() takes 1 positional argument but 2 were given
Traceback (most recent call last):
  File "C:\Users\aliak\src\CODE_PROJECTS\projectY\projectY.py", line 72, in main
    audio_file = downloader.download_audio(url, args.verbose)
TypeError: download_audio() takes 1 positional argument but 2 were given
2025-04-01 18:04:37 - __main__ - ERROR - An error occurred: download_audio() takes 1 positional argument but 2 were given
Traceback (most recent call last):
  File "C:\Users\aliak\src\CODE_PROJECTS\projectY\projectY.py", line 72, in main
    audio_file = downloader.download_audio(url, args.verbose)
TypeError: download_audio() takes 1 positional argument but 2 were given
2025-04-01 18:04:47 - __main__ - ERROR - An error occurred: download_audio() takes 1 positional argument but 2 were given
Traceback (most recent call last):
  File "C:\Users\aliak\src\CODE_PROJECTS\projectY\projectY.py", line 72, in main
    audio_file = downloader.download_audio(url, args.verbose)
TypeError: download_audio() takes 1 positional argument but 2 were given
2025-04-01 18:04:53 - __main__ - ERROR - An error occurred: download_audio() takes 1 positional argument but 2 were given
Traceback (most recent call last):
  File "C:\Users\aliak\src\CODE_PROJECTS\projectY\projectY.py", line 72, in main
    audio_file = downloader.download_audio(url, args.verbose)
TypeError: download_audio() takes 1 positional argument but 2 were given
2025-04-01 18:05:07 - __main__ - ERROR - An error occurred: download_audio() takes 1 positional argument but 2 were given
Traceback (most recent call last):
  File "C:\Users\aliak\src\CODE_PROJECTS\projectY\projectY.py", line 72, in main
    audio_file = downloader.download_audio(url, args.verbose)
TypeError: download_audio() takes 1 positional argument but 2 were given
2025-04-01 18:07:43 - __main__ - ERROR - An error occurred: extract_predictions() missing 1 required positional argument: 'verbose'
Traceback (most recent call last):
  File "C:\Users\aliak\src\CODE_PROJECTS\projectY\projectY.py", line 84, in main
    prediction_list = prediction_extractor.extract_predictions(
TypeError: extract_predictions() missing 1 required positional argument: 'verbose'
2025-04-01 18:10:00 - projectY_modules.downloader - ERROR - Failed to download video: ERROR: [generic] '$ python projectY.py' is not a valid URL. Set --default-search "ytsearch" (or run  yt-dlp "ytsearch:$ python projectY.py" ) to search YouTube
2025-04-01 18:10:00 - __main__ - ERROR - An error occurred: ERROR: [generic] '$ python projectY.py' is not a valid URL. Set --default-search "ytsearch" (or run  yt-dlp "ytsearch:$ python projectY.py" ) to search YouTube
Traceback (most recent call last):
  File "C:\Users\aliak\.conda\envs\y_env\lib\site-packages\yt_dlp\YoutubeDL.py", line 1653, in wrapper
    return func(self, *args, **kwargs)
  File "C:\Users\aliak\.conda\envs\y_env\lib\site-packages\yt_dlp\YoutubeDL.py", line 1788, in __extract_info
    ie_result = ie.extract(url)
  File "C:\Users\aliak\.conda\envs\y_env\lib\site-packages\yt_dlp\extractor\common.py", line 748, in extract
    ie_result = self._real_extract(url)
  File "C:\Users\aliak\.conda\envs\y_env\lib\site-packages\yt_dlp\extractor\generic.py", line 2375, in _real_extract
    raise ExtractorError(
yt_dlp.utils.ExtractorError: [generic] '$ python projectY.py' is not a valid URL. Set --default-search "ytsearch" (or run  yt-dlp "ytsearch:$ python projectY.py" ) to search YouTube

During handling of the above exception, another exception occurred:

Traceback (most recent call last):
  File "C:\Users\aliak\src\CODE_PROJECTS\projectY\projectY.py", line 72, in main
    audio_file = downloader.download_audio(url)
  File "C:\Users\aliak\src\CODE_PROJECTS\projectY\projectY_modules\downloader.py", line 20, in download_audio
    info_dict = ydl.extract_info(youtube_url, download=False)  # Get video info without downloading
  File "C:\Users\aliak\.conda\envs\y_env\lib\site-packages\yt_dlp\YoutubeDL.py", line 1642, in extract_info
    return self.__extract_info(url, self.get_info_extractor(key), download, extra_info, process)
  File "C:\Users\aliak\.conda\envs\y_env\lib\site-packages\yt_dlp\YoutubeDL.py", line 1671, in wrapper
    self.report_error(str(e), e.format_traceback())
  File "C:\Users\aliak\.conda\envs\y_env\lib\site-packages\yt_dlp\YoutubeDL.py", line 1111, in report_error
    self.trouble(f'{self._format_err("ERROR:", self.Styles.ERROR)} {message}', *args, **kwargs)
  File "C:\Users\aliak\.conda\envs\y_env\lib\site-packages\yt_dlp\YoutubeDL.py", line 1050, in trouble
    raise DownloadError(message, exc_info)
yt_dlp.utils.DownloadError: ERROR: [generic] '$ python projectY.py' is not a valid URL. Set --default-search "ytsearch" (or run  yt-dlp "ytsearch:$ python projectY.py" ) to search YouTube
2025-04-01 18:10:05 - projectY_modules.downloader - ERROR - Failed to download video: ERROR: [generic] 'Enter the YouTube video URL: https://www.youtube.com/watch?v=2-RdwZ51CUs' is not a valid URL. Set --default-search "ytsearch" (or run  yt-dlp "ytsearch:Enter the YouTube video URL: https://www.youtube.com/watch?v=2-RdwZ51CUs" ) to search YouTube
2025-04-01 18:10:05 - __main__ - ERROR - An error occurred: ERROR: [generic] 'Enter the YouTube video URL: https://www.youtube.com/watch?v=2-RdwZ51CUs' is not a valid URL. Set --default-search "ytsearch" (or run  yt-dlp "ytsearch:Enter the YouTube video URL: https://www.youtube.com/watch?v=2-RdwZ51CUs" ) to search YouTube
Traceback (most recent call last):
  File "C:\Users\aliak\.conda\envs\y_env\lib\site-packages\yt_dlp\YoutubeDL.py", line 1653, in wrapper
    return func(self, *args, **kwargs)
  File "C:\Users\aliak\.conda\envs\y_env\lib\site-packages\yt_dlp\YoutubeDL.py", line 1788, in __extract_info
    ie_result = ie.extract(url)
  File "C:\Users\aliak\.conda\envs\y_env\lib\site-packages\yt_dlp\extractor\common.py", line 748, in extract
    ie_result = self._real_extract(url)
  File "C:\Users\aliak\.conda\envs\y_env\lib\site-packages\yt_dlp\extractor\generic.py", line 2375, in _real_extract
    raise ExtractorError(
yt_dlp.utils.ExtractorError: [generic] 'Enter the YouTube video URL: https://www.youtube.com/watch?v=2-RdwZ51CUs' is not a valid URL. Set --default-search "ytsearch" (or run  yt-dlp "ytsearch:Enter the YouTube video URL: https://www.youtube.com/watch?v=2-RdwZ51CUs" ) to search YouTube

During handling of the above exception, another exception occurred:

Traceback (most recent call last):
  File "C:\Users\aliak\src\CODE_PROJECTS\projectY\projectY.py", line 72, in main
    audio_file = downloader.download_audio(url)
  File "C:\Users\aliak\src\CODE_PROJECTS\projectY\projectY_modules\downloader.py", line 20, in download_audio
    info_dict = ydl.extract_info(youtube_url, download=False)  # Get video info without downloading
  File "C:\Users\aliak\.conda\envs\y_env\lib\site-packages\yt_dlp\YoutubeDL.py", line 1642, in extract_info
    return self.__extract_info(url, self.get_info_extractor(key), download, extra_info, process)
  File "C:\Users\aliak\.conda\envs\y_env\lib\site-packages\yt_dlp\YoutubeDL.py", line 1671, in wrapper
    self.report_error(str(e), e.format_traceback())
  File "C:\Users\aliak\.conda\envs\y_env\lib\site-packages\yt_dlp\YoutubeDL.py", line 1111, in report_error
    self.trouble(f'{self._format_err("ERROR:", self.Styles.ERROR)} {message}', *args, **kwargs)
  File "C:\Users\aliak\.conda\envs\y_env\lib\site-packages\yt_dlp\YoutubeDL.py", line 1050, in trouble
    raise DownloadError(message, exc_info)
yt_dlp.utils.DownloadError: ERROR: [generic] 'Enter the YouTube video URL: https://www.youtube.com/watch?v=2-RdwZ51CUs' is not a valid URL. Set --default-search "ytsearch" (or run  yt-dlp "ytsearch:Enter the YouTube video URL: https://www.youtube.com/watch?v=2-RdwZ51CUs" ) to search YouTube
2025-04-01 18:23:18 - projectY_modules.transcriber - WARNING - File size (42.10MB) exceeds Whisper API limit of 25MB
